<?xml version='1.0'?>
<sdf version='1.6'>
  <world name='manipulator'>
    <physics name="1ms" type="ode">
      <max_step_size>0.001</max_step_size>
      <real_time_factor>1.0</real_time_factor>
    </physics>
    <plugin
      filename="libignition-gazebo-physics-system.so"
      name="ignition::gazebo::systems::Physics">
    </plugin>
    <plugin
      filename="libignition-gazebo-user-commands-system.so"
      name="ignition::gazebo::systems::UserCommands">
    </plugin>
    <plugin
      filename="libignition-gazebo-scene-broadcaster-system.so"
      name="ignition::gazebo::systems::SceneBroadcaster">
    </plugin>

    <gui fullscreen='0'>
      <!-- 3D scene -->
      <plugin filename='GzScene3D' name='3D View'>
        <ignition-gui>
          <title>3D View</title>
          <property type='bool' key='showTitleBar'>false</property>
          <property type='bool' key='resizable'>false</property>
          <property type='double' key='z'>0</property>
          <anchor line='right' target='window' target_line='right'/>
          <anchor line='left' target='window' target_line='left'/>
          <anchor line='top' target='window' target_line='top'/>
          <anchor line='bottom' target='window' target_line='bottom'/>
        </ignition-gui>

        <engine>ogre</engine>
        <scene>scene</scene>
        <ambient_light>0.4 0.4 0.4</ambient_light>
        <background_color>0.8 0.8 0.8</background_color>
        <camera_pose>1 0 0.1 0 0.05 3.14</camera_pose>
      </plugin>

      <!-- World control -->
      <plugin filename='WorldControl' name='World control'>
        <ignition-gui>
          <title>World control</title>
          <property type='bool' key='showTitleBar'>false</property>
          <property type='bool' key='resizable'>false</property>
          <property type='double' key='height'>72</property>
          <property type='double' key='width'>121</property>
          <property type='double' key='z'>1</property>
          <anchor line='left' target='window' target_line='left'/>
          <anchor line='bottom' target='window' target_line='bottom'/>
        </ignition-gui>

        <play_pause>true</play_pause>
        <step>true</step>
        <start_paused>true</start_paused>
        <service>/world/default/control</service>
        <stats_topic>/world/default/stats</stats_topic>
      </plugin>
    </gui>

    <light type='directional' name='sun'>
      <cast_shadows>true</cast_shadows>
      <pose>0 0 10 0 0 0</pose>
      <diffuse>1 1 1 1</diffuse>
      <specular>0.5 0.5 0.5 1</specular>
      <attenuation>
        <range>1000</range>
        <constant>0.9</constant>
        <linear>0.01</linear>
        <quadratic>0.001</quadratic>
      </attenuation>
      <direction>-0.5 0.1 -0.9</direction>
    </light>
    
    <model name='ground_plane'>
      <static>true</static>
      <link name='link'>
        <collision name='collision'>
          <geometry>
            <plane>
              <normal>0 0 1</normal>
            </plane>
          </geometry>
        </collision>
        <visual name='visual'>
          <geometry>
            <plane>
              <normal>0 0 1</normal>
              <size>100 100</size>
            </plane>
          </geometry>
          <material>
            <ambient>0.8 0.8 0.8 1</ambient>
            <diffuse>0.8 0.8 0.8 1</diffuse>
            <specular>0.8 0.8 0.8 1</specular>
          </material>
        </visual>
      </link>
    </model>
    
    <model name='open_manipulator'>
      <pose>0 0 0 0 0 0</pose>
      <link name='link1'>
        <pose frame=''>0 0 0 0 -0 0</pose>
        <inertial>
          <pose frame=''>0.000309 0 -0.000122 0 -0 0</pose>
          <mass>0.07912</mass>
          <inertia>
            <ixx>1.25052e-05</ixx>
            <ixy>0</ixy>
            <ixz>-1.78552e-07</ixz>
            <iyy>2.18984e-05</iyy>
            <iyz>0</iyz>
            <izz>1.92674e-05</izz>
          </inertia>
        </inertial>
        <collision name='link1_collision'>
          <pose frame=''>0 0 0 0 -0 0</pose>
          <geometry>
            <mesh>
              <scale>0.001 0.001 0.001</scale>
              <uri>file:///home/kaito/ign_ws/src/open_manipulator_ign/models/openmanipulator/meshes/chain_link1.stl</uri>
            </mesh>
          </geometry>
        </collision>
        <visual name='link1_visual'>
          <pose frame=''>0 0 0 0 -0 0</pose>
          <geometry>
            <mesh>
              <scale>0.001 0.001 0.001</scale>
              <uri>file:///home/kaito/ign_ws/src/open_manipulator_ign/models/openmanipulator/meshes/chain_link1.stl</uri>
            </mesh>
          </geometry>
          <material>
            <ambient>0.5 0.5 1.0 1</ambient>
            <diffuse>0.5 0.5 1.0 1</diffuse>
            <specular>0.5 0.5 0.5 1.0</specular>
          </material>
        </visual>
      </link>
      <joint name='world_fixed' type='fixed'>
        <child>link1</child>
        <parent>world</parent>
      </joint>
      <link name='link2'>
        <pose frame=''>0.012 0 0.017 0 -0 0</pose>
        <inertial>
          <pose frame=''>-0.000302 0.00054 0.047434 0 -0 0</pose>
          <mass>0.0984068</mass>
          <inertia>
            <ixx>3.45434e-05</ixx>
            <ixy>-1.60311e-08</ixy>
            <ixz>-3.83752e-07</ixz>
            <iyy>3.26893e-05</iyy>
            <iyz>2.85119e-08</iyz>
            <izz>1.88503e-05</izz>
          </inertia>
        </inertial>
        <collision name='link2_collision'>
          <pose frame=''>0 0 0.019 0 -0 0</pose>
          <geometry>
            <mesh>
              <scale>0.001 0.001 0.001</scale>
              <uri>file:///home/kaito/ign_ws/src/open_manipulator_ign/models/openmanipulator/meshes/chain_link2.stl</uri>
            </mesh>
          </geometry>
        </collision>
        <visual name='link2_visual'>
          <pose frame=''>0 0 0.019 0 -0 0</pose>
          <geometry>
            <mesh>
              <scale>0.001 0.001 0.001</scale>
              <uri>file:///home/kaito/ign_ws/src/open_manipulator_ign/models/openmanipulator/meshes/chain_link2.stl</uri>
            </mesh>
          </geometry>
          <material>
            <ambient>0.5 0.5 1.0 1</ambient>
            <diffuse>0.5 0.5 1.0 1</diffuse>
            <specular>0.5 0.5 0.5 1.0</specular>
          </material>
        </visual>
      </link>
      <joint name='joint1' type='revolute'>
        <child>link2</child>
        <parent>link1</parent>
        <axis>
          <xyz>0 0 1</xyz>
          <limit>
            <lower>-2.82743</lower>
            <upper>2.82743</upper>
            <effort>1</effort>
            <velocity>4.8</velocity>
          </limit>
          <dynamics>
            <spring_reference>0</spring_reference>
            <spring_stiffness>0</spring_stiffness>
          </dynamics>
          <use_parent_model_frame>1</use_parent_model_frame>
        </axis>
      </joint>
      <link name='link3'>
        <pose frame=''>0.012 0 0.0765 0 -0 0</pose>
        <inertial>
          <pose frame=''>0.010308 0.000377 0.101702 0 -0 0</pose>
          <mass>0.138509</mass>
          <inertia>
            <ixx>0.000330554</ixx>
            <ixy>-9.7941e-08</ixy>
            <ixz>-3.85057e-05</ixz>
            <iyy>0.000342904</iyy>
            <iyz>-1.57175e-06</iyz>
            <izz>6.03465e-05</izz>
          </inertia>
        </inertial>
        <collision name='link3_collision'>
          <pose frame=''>0 0 0 0 -0 0</pose>
          <geometry>
            <mesh>
              <scale>0.001 0.001 0.001</scale>
              <uri>file:///home/kaito/ign_ws/src/open_manipulator_ign/models/openmanipulator/meshes/chain_link3.stl</uri>
            </mesh>
          </geometry>
        </collision>
        <visual name='link3_visual'>
          <pose frame=''>0 0 0 0 -0 0</pose>
          <geometry>
            <mesh>
              <scale>0.001 0.001 0.001</scale>
              <uri>file:///home/kaito/ign_ws/src/open_manipulator_ign/models/openmanipulator/meshes/chain_link3.stl</uri>
            </mesh>
          </geometry>
          <material>
            <ambient>0.5 0.5 1.0 1</ambient>
            <diffuse>0.5 0.5 1.0 1</diffuse>
            <specular>0.5 0.5 0.5 1.0</specular>
          </material>
        </visual>
      </link>
      <joint name='joint2' type='revolute'>
        <child>link3</child>
        <parent>link2</parent>
        <axis>
          <xyz>0 1 0</xyz>
          <limit>
            <lower>-1.79071</lower>
            <upper>1.5708</upper>
            <effort>1</effort>
            <velocity>4.8</velocity>
          </limit>
          <dynamics>
            <spring_reference>0</spring_reference>
            <spring_stiffness>0</spring_stiffness>
          </dynamics>
          <use_parent_model_frame>1</use_parent_model_frame>
        </axis>
      </joint>
      <link name='link4'>
        <pose frame=''>0.036 0 0.2045 0 -0 0</pose>
        <inertial>
          <pose frame=''>0.09091 0.000389 0.000224 0 -0 0</pose>
          <mass>0.132746</mass>
          <inertia>
            <ixx>3.06542e-05</ixx>
            <ixy>-1.27642e-06</ixy>
            <ixz>-2.68744e-07</ixz>
            <iyy>0.000242303</iyy>
            <iyz>1.15595e-08</iyz>
            <izz>0.000251551</izz>
          </inertia>
        </inertial>
        <collision name='link4_collision'>
          <pose frame=''>0 0 0 0 -0 0</pose>
          <geometry>
            <mesh>
              <scale>0.001 0.001 0.001</scale>
              <uri>file:///home/kaito/ign_ws/src/open_manipulator_ign/models/openmanipulator/meshes/chain_link4.stl</uri>
            </mesh>
          </geometry>
        </collision>
        <visual name='link4_visual'>
          <pose frame=''>0 0 0 0 -0 0</pose>
          <geometry>
            <mesh>
              <scale>0.001 0.001 0.001</scale>
              <uri>file:///home/kaito/ign_ws/src/open_manipulator_ign/models/openmanipulator/meshes/chain_link4.stl</uri>
            </mesh>
          </geometry>
          <material>
            <ambient>0.5 0.5 1.0 1</ambient>
            <diffuse>0.5 0.5 1.0 1</diffuse>
            <specular>0.5 0.5 0.5 1.0</specular>
          </material>
        </visual>
      </link>
      <joint name='joint3' type='revolute'>
        <child>link4</child>
        <parent>link3</parent>
        <axis>
          <xyz>0 1 0</xyz>
          <limit>
            <lower>-0.942478</lower>
            <upper>1.3823</upper>
            <effort>1</effort>
            <velocity>4.8</velocity>
          </limit>
          <dynamics>
            <spring_reference>0</spring_reference>
            <spring_stiffness>0</spring_stiffness>
          </dynamics>
          <use_parent_model_frame>1</use_parent_model_frame>
        </axis>
      </joint>
      <link name='link5'>
        <pose frame=''>0.16 0 0.2045 0 -0 0</pose>
        <inertial>
          <pose frame=''>0.044774 0 0.008852 0 -0 0</pose>
          <mass>0.144276</mass>
          <inertia>
            <ixx>8.19497e-05</ixx>
            <ixy>2.99238e-11</ixy>
            <ixz>-2.9172e-07</ixz>
            <iyy>8.37031e-05</iyy>
            <iyz>-3.26124e-12</iyz>
            <izz>0.000100771</izz>
          </inertia>
        </inertial>
        <collision name='link5_collision'>
          <pose frame=''>0 0 0 0 -0 0</pose>
          <geometry>
            <mesh>
              <scale>0.001 0.001 0.001</scale>
              <uri>file:///home/kaito/ign_ws/src/open_manipulator_ign/models/openmanipulator/meshes/chain_link5.stl</uri>
            </mesh>
          </geometry>
        </collision>
        <visual name='link5_visual'>
          <pose frame=''>0 0 0 0 -0 0</pose>
          <geometry>
            <mesh>
              <scale>0.001 0.001 0.001</scale>
              <uri>file:///home/kaito/ign_ws/src/open_manipulator_ign/models/openmanipulator/meshes/chain_link5.stl</uri>
            </mesh>
          </geometry>
          <material>
            <ambient>0.5 0.5 1.0 1</ambient>
            <diffuse>0.5 0.5 1.0 1</diffuse>
            <specular>0.5 0.5 0.5 1.0</specular>
          </material>
        </visual>
        <visual name='link5_fixed_joint_lump__end_effector_link_visual_1'>
          <pose frame=''>0.126 0 0 0 -0 0</pose>
          <geometry>
            <box>
              <size>0.01 0.01 0.01</size>
            </box>
          </geometry>
        </visual>
      </link>
      <joint name='joint4' type='revolute'>
        <child>link5</child>
        <parent>link4</parent>
        <axis>
          <xyz>0 1 0</xyz>
          <limit>
            <lower>-1.79071</lower>
            <upper>2.04204</upper>
            <effort>1</effort>
            <velocity>4.8</velocity>
          </limit>
          <dynamics>
            <spring_reference>0</spring_reference>
            <spring_stiffness>0</spring_stiffness>
          </dynamics>
          <use_parent_model_frame>1</use_parent_model_frame>
        </axis>
      </joint>

      <link name='gripper_link'>
        <pose frame=''>0.2417 0.021 0.2045 0 -0 0</pose>
        <inertial>
          <pose frame=''>0.036372 0.03457 -0 0 -0 0</pose>
          <mass>0.0322181</mass>
          <inertia>
            <ixx>9.55688e-06</ixx>
            <ixy>2.84246e-06</ixy>
            <ixz>-3.28292e-10</ixz>
            <iyy>2.25529e-05</iyy>
            <iyz>-3.14636e-10</iyz>
            <izz>1.76053e-05</izz>
          </inertia>
        </inertial>
        <collision name='gripper_link_collision'>
          <pose frame=''>0 0 0 0 -0 0</pose>
          <geometry>
            <mesh>
              <scale>0.001 0.001 0.001</scale>
              <uri>file:///home/kaito/ign_ws/src/open_manipulator_ign/models/openmanipulator/meshes/chain_link_grip_l.stl</uri>
            </mesh>
          </geometry>
        </collision>
        <visual name='gripper_link_visual'>
          <pose frame=''>0 0 0 0 -0 0</pose>
          <geometry>
            <mesh>
              <scale>0.001 0.001 0.001</scale>
              <uri>file:///home/kaito/ign_ws/src/open_manipulator_ign/models/openmanipulator/meshes/chain_link_grip_l.stl</uri>
            </mesh>
          </geometry>
          <material>
            <ambient>0.5 0.5 1.0 1</ambient>
            <diffuse>0.5 0.5 1.0 1</diffuse>
            <specular>0.5 0.5 0.5 1.0</specular>
          </material>
        </visual>
      </link>
    
      <joint name='gripper' type='prismatic'>
        <child>gripper_link</child>
        <parent>link5</parent>
        <axis>
          <xyz>0 1 0</xyz>
          <limit>
            <lower>-0.01</lower>
            <upper>0.019</upper>
            <effort>1</effort>
            <velocity>4.8</velocity>
          </limit>
          <dynamics>
            <spring_reference>0</spring_reference>
            <spring_stiffness>0</spring_stiffness>
          </dynamics>
          <use_parent_model_frame>1</use_parent_model_frame>
        </axis>
      </joint>
      <link name='gripper_link_sub'>
        <pose frame=''>0.2417 -0.021 0.2045 0 -0 0</pose>
        <inertial>
          <pose frame=''>0.036372 -0.03457 -0 0 -0 0</pose>
          <mass>0.0322181</mass>
          <inertia>
            <ixx>9.55688e-06</ixx>
            <ixy>2.84246e-06</ixy>
            <ixz>-3.28292e-10</ixz>
            <iyy>2.25529e-05</iyy>
            <iyz>-3.14636e-10</iyz>
            <izz>1.76053e-05</izz>
          </inertia>
        </inertial>
        <collision name='gripper_link_sub_collision'>
          <pose frame=''>0 -0 0 0 -0 0</pose>
          <geometry>
            <mesh>
              <scale>0.001 0.001 0.001</scale>
              <uri>file:///home/kaito/ign_ws/src/open_manipulator_ign/models/openmanipulator/meshes/chain_link_grip_r.stl</uri>
            </mesh>
          </geometry>
        </collision>
        <visual name='gripper_link_sub_visual'>
          <pose frame=''>0 -0 0 0 -0 0</pose>
          <geometry>
            <mesh>
              <scale>0.001 0.001 0.001</scale>
              <uri>file:///home/kaito/ign_ws/src/open_manipulator_ign/models/openmanipulator/meshes/chain_link_grip_r.stl</uri>
            </mesh>
          </geometry>
          <material>
            <ambient>0.5 0.5 1.0 1</ambient>
            <diffuse>0.5 0.5 1.0 1</diffuse>
            <specular>0.5 0.5 0.5 1.0</specular>
          </material>
        </visual>
      </link>
      <joint name='gripper_sub' type='prismatic'>
        <child>gripper_link_sub</child>
        <parent>link5</parent>
        <axis>
          <xyz>0 -1 0</xyz>
          <limit>
            <lower>-0.01</lower>
            <upper>0.019</upper>
            <effort>1</effort>
            <velocity>4.8</velocity>
          </limit>
          <dynamics>
            <spring_reference>0</spring_reference>
            <spring_stiffness>0</spring_stiffness>
          </dynamics>
          <use_parent_model_frame>1</use_parent_model_frame>
        </axis>
      </joint>

      <plugin
        filename="libignition-gazebo-joint-state-publisher-system.so"
        name="ignition::gazebo::systems::JointStatePublisher">
      </plugin>
    </model>

  </world>
</sdf>
